<?xml version="1.0" ?>
<!-- =================================================================================== -->
<!-- |    This document was autogenerated by xacro from /workspaces/src/franka_description/robots/fr3/fr3.urdf.xacro | -->
<!-- |    EDITING THIS FILE BY HAND IS NOT RECOMMENDED                                 | -->
<!-- =================================================================================== -->
<robot name="fr3">
  <!-- safety_distance: Minimum safety distance in [m] by which the collision volumes are expanded and which is enforced during robot motions -->
  <!-- robot_type: Namespace of the robot arm. Serves to differentiate between arms in case of multiple instances. -->
  <!-- joint_limits: description of the joint limits that comes from a YAML file. Example definition: ${xacro.load_yaml('$(find franka_description)/robots/fr3/joint_limits.yaml')} -->
  <!-- kinematics: description of the kinematics that comes from a YAML file. Example definition: ${xacro.load_yaml('$(find franka_description)/robots/fr3/kinematics.yaml')} -->
  <!-- inertials: description of the inertials that comes from a YAML file. Example definition: ${xacro.load_yaml('$(find franka_description)/robots/fr3/inertials.yaml')} -->
  <!-- dynamics: description of the dynamics that comes from a YAML file. Example definition: ${xacro.load_yaml('$(find franka_description)/robots/fr3/dynamics.yaml')} -->
  <link name="base">
      </link>
  <joint name="fr3_base_joint" type="fixed">
    <parent link="base"/>
    <child link="fr3_link0"/>
    <origin rpy="0 0 0" xyz="0 0 0"/>
  </joint>
  <!-- sub-link defining detailed meshes for collision with environment -->
  <link name="fr3_link0">
    <visual name="fr3_link0_visual">
      <geometry>
        <mesh filename="package://franka_description/meshes/robots/fr3/visual/link0.dae"/>
      </geometry>
    </visual>
    <collision name="fr3_link0_collision">
      <geometry>
        <mesh filename="package://franka_description/meshes/robots/fr3/collision/link0.stl"/>
      </geometry>
    </collision>
    <inertial>
      <origin rpy="0 0 0" xyz="-0.0172 0.0004 0.0745"/>
      <mass value="2.3966"/>
      <inertia ixx="0.009" ixy="0.0" ixz="0.002" iyy="0.0115" iyz="0.0" izz="0.0085"/>
    </inertial>
  </link>
  <link name="fr3_link0_accelerometer_top">
      </link>
  <joint name="fr3_link0_accelerometer_top_joint" type="fixed">
    <origin rpy="3.14159 0 0" xyz="0 0 0.05"/>
    <parent link="fr3_link0"/>
    <child link="fr3_link0_accelerometer_top"/>
  </joint>
  <link name="fr3_link0_accelerometer_bottom">
      </link>
  <joint name="fr3_link0_accelerometer_bottom_joint" type="fixed">
    <origin rpy="0 0 0" xyz="0 0 0.06"/>
    <parent link="fr3_link0"/>
    <child link="fr3_link0_accelerometer_bottom"/>
  </joint>
  <!-- sub-link defining detailed meshes for collision with environment -->
  <link name="fr3_link1">
    <visual name="fr3_link1_visual">
      <geometry>
        <mesh filename="package://franka_description/meshes/robots/fr3/visual/link1.dae"/>
      </geometry>
    </visual>
    <collision name="fr3_link1_collision">
      <geometry>
        <mesh filename="package://franka_description/meshes/robots/fr3/collision/link1.stl"/>
      </geometry>
    </collision>
    <inertial>
      <origin rpy="0 0 0" xyz="0.0000004128 -0.0181251324 -0.0386035970"/>
      <mass value="2.9274653454"/>
      <inertia ixx="0.023927316485107913" ixy="1.3317903455714081e-05" ixz="-0.00011404774918616684" iyy="0.0224821613275756" iyz="-0.0019950320628240115" izz="0.006350098258530016"/>
    </inertial>
  </link>
  <link name="fr3_link1_accelerometer_top">
      </link>
  <joint name="fr3_link1_accelerometer_top_joint" type="fixed">
    <origin rpy="1.5708 0 0" xyz="0 -0.1 0.0"/>
    <parent link="fr3_link1"/>
    <child link="fr3_link1_accelerometer_top"/>
  </joint>
  <link name="fr3_link1_accelerometer_bottom">
      </link>
  <joint name="fr3_link1_accelerometer_bottom_joint" type="fixed">
    <origin rpy="-1.5708 0 0" xyz="0 -0.09 0.0"/>
    <parent link="fr3_link1"/>
    <child link="fr3_link1_accelerometer_bottom"/>
  </joint>
  <joint name="fr3_joint1" type="revolute">
    <origin rpy="0 0 0" xyz="0 0 0.333"/>
    <parent link="fr3_link0"/>
    <child link="fr3_link1"/>
    <axis xyz="0 0 1"/>
    <limit effort="87.0" lower="-2.9007" upper="2.9007" velocity="2.62"/>
    <safety_controller k_position="100.0" k_velocity="40.0" soft_lower_limit="-2.9007" soft_upper_limit="2.9007"/>
    <position_based_velocity_limits deceleration_limit="6.0" velocity_offset="0.652"/>
    <dynamics D="1" K="7000" damping="0.003" friction="0.2" mu_coulomb="0" mu_viscous="16"/>
  </joint>
  <!-- sub-link defining detailed meshes for collision with environment -->
  <link name="fr3_link2">
    <visual name="fr3_link2_visual">
      <geometry>
        <mesh filename="package://franka_description/meshes/robots/fr3/visual/link2.dae"/>
      </geometry>
    </visual>
    <collision name="fr3_link2_collision">
      <geometry>
        <mesh filename="package://franka_description/meshes/robots/fr3/collision/link2.stl"/>
      </geometry>
    </collision>
    <inertial>
      <origin rpy="0 0 0" xyz="0.0031828864 -0.0743221644 0.0088146084"/>
      <mass value="2.9355370338"/>
      <inertia ixx="0.041938946257609425" ixy="0.00020257331521090626" ixz="0.004077784227179924" iyy="0.02514514885014724" iyz="-0.0042252158006570156" izz="0.06170214472888839"/>
    </inertial>
  </link>
  <link name="fr3_link2_accelerometer_top">
      </link>
  <joint name="fr3_link2_accelerometer_top_joint" type="fixed">
    <origin rpy="-1.5708 0 0" xyz="0 -0.13 0"/>
    <parent link="fr3_link2"/>
    <child link="fr3_link2_accelerometer_top"/>
  </joint>
  <link name="fr3_link2_accelerometer_bottom">
      </link>
  <joint name="fr3_link2_accelerometer_bottom_joint" type="fixed">
    <origin rpy="1.5708 0 0" xyz="0 -0.14 0"/>
    <parent link="fr3_link2"/>
    <child link="fr3_link2_accelerometer_bottom"/>
  </joint>
  <joint name="fr3_joint2" type="revolute">
    <origin rpy="-1.570796326794897 0 0" xyz="0 0 0"/>
    <parent link="fr3_link1"/>
    <child link="fr3_link2"/>
    <axis xyz="0 0 1"/>
    <limit effort="87.0" lower="-1.8361" upper="1.8361" velocity="2.62"/>
    <safety_controller k_position="100.0" k_velocity="40.0" soft_lower_limit="-1.8361" soft_upper_limit="1.8361"/>
    <position_based_velocity_limits deceleration_limit="2.585" velocity_offset="0.25"/>
    <dynamics D="1" K="7000" damping="0.003" friction="0.2" mu_coulomb="0" mu_viscous="16"/>
  </joint>
  <!-- sub-link defining detailed meshes for collision with environment -->
  <link name="fr3_link3">
    <visual name="fr3_link3_visual">
      <geometry>
        <mesh filename="package://franka_description/meshes/robots/fr3/visual/link3.dae"/>
      </geometry>
    </visual>
    <collision name="fr3_link3_collision">
      <geometry>
        <mesh filename="package://franka_description/meshes/robots/fr3/collision/link3.stl"/>
      </geometry>
    </collision>
    <inertial>
      <origin rpy="0 0 0" xyz="0.0407015686 -0.0048200565 -0.0289730823"/>
      <mass value="2.2449013699"/>
      <inertia ixx="0.02410142547240885" ixy="0.002404694559042109" ixz="-0.002856269270114313" iyy="0.01974053266708178" iyz="-0.002104212683891874" izz="0.019044494482244823"/>
    </inertial>
  </link>
  <link name="fr3_link3_accelerometer_top">
      </link>
  <joint name="fr3_link3_accelerometer_top_joint" type="fixed">
    <origin rpy="-1.5708 0 0" xyz="0.0825 0.05 0"/>
    <parent link="fr3_link3"/>
    <child link="fr3_link3_accelerometer_top"/>
  </joint>
  <link name="fr3_link3_accelerometer_bottom">
      </link>
  <joint name="fr3_link3_accelerometer_bottom_joint" type="fixed">
    <origin rpy="1.5708 0 0" xyz="0.0825 0.04 0"/>
    <parent link="fr3_link3"/>
    <child link="fr3_link3_accelerometer_bottom"/>
  </joint>
  <joint name="fr3_joint3" type="revolute">
    <origin rpy="1.570796326794897 0 0" xyz="0 -0.316 0"/>
    <parent link="fr3_link2"/>
    <child link="fr3_link3"/>
    <axis xyz="0 0 1"/>
    <limit effort="87.0" lower="-2.9007" upper="2.9007" velocity="2.62"/>
    <safety_controller k_position="100.0" k_velocity="40.0" soft_lower_limit="-2.9007" soft_upper_limit="2.9007"/>
    <position_based_velocity_limits deceleration_limit="3.5" velocity_offset="0.2005"/>
    <dynamics D="1" K="7000" damping="0.003" friction="0.2" mu_coulomb="0" mu_viscous="16"/>
  </joint>
  <!-- sub-link defining detailed meshes for collision with environment -->
  <link name="fr3_link4">
    <visual name="fr3_link4_visual">
      <geometry>
        <mesh filename="package://franka_description/meshes/robots/fr3/visual/link4.dae"/>
      </geometry>
    </visual>
    <collision name="fr3_link4_collision">
      <geometry>
        <mesh filename="package://franka_description/meshes/robots/fr3/collision/link4.stl"/>
      </geometry>
    </collision>
    <inertial>
      <origin rpy="0 0 0" xyz="-0.0459100965 0.0630492960 -0.0085187868"/>
      <mass value="2.6155955791"/>
      <inertia ixx="0.03452998321913202" ixy="0.01322552265982813" ixz="0.01015142998484113" iyy="0.028881621933049058" iyz="-0.0009762833870704552" izz="0.04125471171146641"/>
    </inertial>
  </link>
  <link name="fr3_link4_accelerometer_top">
      </link>
  <joint name="fr3_link4_accelerometer_top_joint" type="fixed">
    <origin rpy="1.5708 0 0" xyz="-0.0825 0.05 0"/>
    <parent link="fr3_link4"/>
    <child link="fr3_link4_accelerometer_top"/>
  </joint>
  <link name="fr3_link4_accelerometer_bottom">
      </link>
  <joint name="fr3_link4_accelerometer_bottom_joint" type="fixed">
    <origin rpy="-1.5708 0 0" xyz="-0.0825 0.06 0"/>
    <parent link="fr3_link4"/>
    <child link="fr3_link4_accelerometer_bottom"/>
  </joint>
  <joint name="fr3_joint4" type="revolute">
    <origin rpy="1.570796326794897 0 0" xyz="0.0825 0 0"/>
    <parent link="fr3_link3"/>
    <child link="fr3_link4"/>
    <axis xyz="0 0 1"/>
    <limit effort="87.0" lower="-3.077" upper="-0.1169" velocity="2.62"/>
    <safety_controller k_position="100.0" k_velocity="40.0" soft_lower_limit="-3.077" soft_upper_limit="-0.1169"/>
    <position_based_velocity_limits deceleration_limit="4.0" velocity_offset="0.3542"/>
    <dynamics D="1" K="7000" damping="0.003" friction="0.2" mu_coulomb="0" mu_viscous="16"/>
  </joint>
  <!-- sub-link defining detailed meshes for collision with environment -->
  <link name="fr3_link5">
    <visual name="fr3_link5_visual">
      <geometry>
        <mesh filename="package://franka_description/meshes/robots/fr3/visual/link5.dae"/>
      </geometry>
    </visual>
    <collision name="fr3_link5_collision">
      <geometry>
        <mesh filename="package://franka_description/meshes/robots/fr3/collision/link5.stl"/>
      </geometry>
    </collision>
    <inertial>
      <origin rpy="0 0 0" xyz="-0.0016039605 0.0292536262 -0.0972965990"/>
      <mass value="2.3271207594"/>
      <inertia ixx="0.051610278463662895" ixy="-0.005715173387783472" ixz="-0.0035673167625872135" iyy="0.04787729713371481" iyz="0.010673985108535986" izz="0.016423625579357254"/>
    </inertial>
  </link>
  <link name="fr3_link5_accelerometer_top">
      </link>
  <joint name="fr3_link5_accelerometer_top_joint" type="fixed">
    <origin rpy="-1.5708 0 0" xyz="0 0.11 0"/>
    <parent link="fr3_link5"/>
    <child link="fr3_link5_accelerometer_top"/>
  </joint>
  <link name="fr3_link5_accelerometer_bottom">
      </link>
  <joint name="fr3_link5_accelerometer_bottom_joint" type="fixed">
    <origin rpy="1.5708 0 0" xyz="0 0.1 0"/>
    <parent link="fr3_link5"/>
    <child link="fr3_link5_accelerometer_bottom"/>
  </joint>
  <joint name="fr3_joint5" type="revolute">
    <origin rpy="-1.570796326794897 0 0" xyz="-0.0825 0.384 0"/>
    <parent link="fr3_link4"/>
    <child link="fr3_link5"/>
    <axis xyz="0 0 1"/>
    <limit effort="12.0" lower="-2.8763" upper="2.8763" velocity="5.26"/>
    <safety_controller k_position="100.0" k_velocity="40.0" soft_lower_limit="-2.8763" soft_upper_limit="2.8763"/>
    <position_based_velocity_limits deceleration_limit="17.0" velocity_offset="0.5738"/>
    <dynamics D="1" K="7000" damping="0.003" friction="0.2" mu_coulomb="0" mu_viscous="16"/>
  </joint>
  <!-- sub-link defining detailed meshes for collision with environment -->
  <link name="fr3_link6">
    <visual name="fr3_link6_visual">
      <geometry>
        <mesh filename="package://franka_description/meshes/robots/fr3/visual/link6.dae"/>
      </geometry>
    </visual>
    <collision name="fr3_link6_collision">
      <geometry>
        <mesh filename="package://franka_description/meshes/robots/fr3/collision/link6.stl"/>
      </geometry>
    </collision>
    <inertial>
      <origin rpy="0 0 0" xyz="0.0597131221 -0.0410294666 -0.0101692726"/>
      <mass value="1.8170376524"/>
      <inertia ixx="0.005412333594383447" ixy="0.006193456360285834" ixz="0.0014219289306117652" iyy="0.014058329545509979" iyz="-0.0013140753741120031" izz="0.016080817924212554"/>
    </inertial>
  </link>
  <joint name="fr3_joint6" type="revolute">
    <origin rpy="1.570796326794897 0 0" xyz="0 0 0"/>
    <parent link="fr3_link5"/>
    <child link="fr3_link6"/>
    <axis xyz="0 0 1"/>
    <limit effort="12.0" lower="0.4398" upper="4.6216" velocity="4.18"/>
    <safety_controller k_position="100.0" k_velocity="40.0" soft_lower_limit="0.4398" soft_upper_limit="4.6216"/>
    <position_based_velocity_limits deceleration_limit="5.5" velocity_offset="0.4885"/>
    <dynamics D="1" K="7000" damping="0.003" friction="0.2" mu_coulomb="0" mu_viscous="16"/>
  </joint>
  <!-- sub-link defining detailed meshes for collision with environment -->
  <link name="fr3_link7">
    <visual name="fr3_link7_visual">
      <geometry>
        <mesh filename="package://franka_description/meshes/robots/fr3/visual/link7.dae"/>
      </geometry>
    </visual>
    <collision name="fr3_link7_collision">
      <geometry>
        <mesh filename="package://franka_description/meshes/robots/fr3/collision/link7.stl"/>
      </geometry>
    </collision>
    <inertial>
      <origin rpy="0 0 0" xyz="0.0045225817 0.0086261921 -0.0161633251"/>
      <mass value="0.6271432862"/>
      <inertia ixx="0.00021092389150104718" ixy="-2.433299114461931e-05" ixz="4.564480393778983e-05" iyy="0.00017718568002411474" iyz="8.744070223226438e-05" izz="5.993190599659971e-05"/>
    </inertial>
  </link>
  <joint name="fr3_joint7" type="revolute">
    <origin rpy="1.570796326794897 0 0" xyz="0.088 0 0"/>
    <parent link="fr3_link6"/>
    <child link="fr3_link7"/>
    <axis xyz="0 0 1"/>
    <limit effort="12.0" lower="-3.0508" upper="3.0508" velocity="5.26"/>
    <safety_controller k_position="100.0" k_velocity="40.0" soft_lower_limit="-3.0508" soft_upper_limit="3.0508"/>
    <position_based_velocity_limits deceleration_limit="17.0" velocity_offset="0.4592"/>
    <dynamics D="1" K="7000" damping="0.003" friction="0.2" mu_coulomb="0" mu_viscous="16"/>
  </joint>
  <link name="fr3_link8"/>
  <joint name="fr3_joint8" type="fixed">
    <origin rpy="0 0 0" xyz="0 0 0.107"/>
    <parent link="fr3_link7"/>
    <child link="fr3_link8"/>
  </joint>

  <!-- ======================== BASE PARAMS ========================= -->
  <!-- ======================== FINGER PARAMS ======================== -->
  <!-- full height from joint to tip. when used,
    the radius of the finger tip sphere will be subtracted
    and one fixed link will be added for the tip. -->
  <!-- ========================= THUMB PARAMS ========================= -->
  <!-- ========================= LIMITS ========================= -->
  <!-- ============================================================================= -->
  <!-- PALM -->
 
  
  <link name="palm_link">
    <visual>
      <geometry>
        <mesh filename="assets/palm.stl" scale="0.001 0.001 0.001"/>
      </geometry>
      <origin rpy="0 3.14 1.57" xyz="0.02 -0.00 -0.1"/>
      <material name="black">
        <color rgba="0.2 0.2 0.2 1"/>
      </material>
    </visual>
    <collision>
      <geometry>
        <mesh filename="assets/palm.stl" scale="0.001 0.001 0.001"/>
      </geometry>
 <origin rpy="0 3.14 1.57" xyz="0.02 -0.00 -0.1"/>
    </collision>
    <inertial>
      <origin rpy="0 0 0" xyz="0 0 0.0475"/>
      <mass value="0.4154"/>
      <inertia ixx="1e-4" ixy="0.0" ixz="0.0" iyy="1e-4" iyz="0.0" izz="1e-4"/>
    </inertial>
  </link>
  <!-- ============================================================================= -->
  <!-- FINGERS -->
  <!-- RIGHT HAND due to which finger is number 0 -->
  <!-- for LEFT HAND switch the sign of the **offset_origin_y** and **finger_angle_r** parameters-->
  <!-- [LINK 0, 4, 8] -->
  <link name="link_0_0">
    <visual>
      <geometry>
        <mesh filename="assets/l1.stl" scale="0.001 0.001 0.001"/>
      </geometry>
      <origin rpy="0 0 -1.57" xyz="-0.025 -0.019 0.165"/>
      <material name="black">
        <color rgba="0.2 0.2 0.2 1"/>
      </material>
    </visual>
    <collision>
      <geometry>
        <mesh filename="assets/l1.stl" scale="0.001 0.001 0.001"/>
      </geometry>
      <origin rpy="0 0 -1.57" xyz="-0.025 -0.019 0.165"/>
    </collision>
    <inertial>
      <mass value="0.0176"/>
      <origin rpy="0 0 0" xyz="0 0 0"/>
      <inertia ixx="1.2854008e-05" ixy="2.04e-08" ixz="1.89e-06" iyy="1.225e-05" iyz="1.51e-07" izz="2.999e-06"/>
    </inertial>
  </link>
  <joint name="joint_0_0" type="revolute">
    <axis xyz="0 0 1"/>
    <limit effort="15" lower="-0.47" upper="0.47" velocity="7"/>
    <parent link="palm_link"/>
    <child link="link_0_0"/>
    <origin rpy="-0.08726646255 0 0" xyz="0.00 0.0405 -0.00945"/>
    <dynamics damping="3" friction="10"/>
  </joint>
  <!-- [LINK 1, 5, 9] -->
  <link name="link_1_0">
    <visual>
      <geometry>
        <mesh filename="assets/l2.stl" scale="0.001 0.001 0.001"/>
      </geometry>
      <origin rpy="0 0 -1.57" xyz="-0.025 -0.019 0.145"/>
      <material name="black"/>
    </visual>
    <collision>
      <geometry>
        <mesh filename="assets/l2.stl" scale="0.001 0.001 0.001"/>
      </geometry>
      <origin rpy="0 0 -1.57" xyz="-0.025 -0.019 0.145"/>
    </collision>
    <inertial>
      <mass value="0.066"/>
      <origin rpy="0 0 0" xyz="0 0 0"/>
      <inertia ixx="6.2497616e-06" ixy="0.0000e-06" ixz="-1.892683e-06" iyy="3.1284129e-05" iyz="0.0000e-06" izz="2.9004797e-05"/>
    </inertial>
  </link>
  <joint name="joint_1_0" type="revolute">
    <limit effort="15" lower="-0.196" upper="1.8" velocity="7"/>
    <axis xyz="0 1 0"/>
    <parent link="link_0_0"/>
    <child link="link_1_0"/>
    <origin xyz="0.00 0 0.021"/>
    <dynamics damping="3" friction="5"/>
  </joint>
  <!-- [LINK 2, 6, 10]-->
  <link name="link_2_0">
    <visual>
      <geometry>
        <mesh filename="assets/l3.stl" scale="0.001 0.001 0.001"/>
      </geometry>
      <origin rpy="0 0 -1.57" xyz="-0.025 -0.019 0.0945"/>
      <material name="black"/>
    </visual>
    <collision>
      <geometry>
        <mesh filename="assets/l3.stl" scale="0.001 0.001 0.001"/>
      </geometry>
      <origin rpy="0 0 -1.57" xyz="-0.025 -0.019 0.0945"/>
    </collision>
    <inertial>
      <mass value="0.0366"/>
      <origin rpy="0 0 0" xyz="0 0 0"/>
      <inertia ixx="3.8070280e-06" ixy="5.7154287e-03" ixz="-9.9708657e-07" iyy="1.4547214e-05" iyz="2.632663e-04" izz="1.2905337e-05"/>
    </inertial>
  </link>
  <joint name="joint_2_0" type="revolute">
    <axis xyz="0 1 0"/>
    <limit effort="15" lower="-0.174" upper="1.709" velocity="7"/>
    <parent link="link_1_0"/>
    <child link="link_2_0"/>
    <origin xyz="0 0 0.051"/>
    <dynamics damping="8" friction="10"/>
  </joint>
  <!-- [LINK 3, 7, 11] -->
  <link name="link_3_0">
    <visual>
      <geometry>
        <mesh filename="assets/l4.stl" scale="0.001 0.001 0.001"/>
      </geometry>
      <origin rpy="0 0 -1.57" xyz="-0.025 -0.019 0.0561"/>
      <material name="black"/>
    </visual>
    <collision>
      <geometry>
        <mesh filename="assets/l4.stl" scale="0.001 0.001 0.001"/>
      </geometry>
      <origin rpy="0 0 -1.57" xyz="-0.025 -0.019 0.0561"/>
    </collision>
    <inertial>
      <mass value="0.00569"/>
      <origin rpy="0 0 0" xyz="0 0 0"/>
      <inertia ixx="1.176928e-06" ixy="5.0891669e-03" ixz="0.000000e-06" iyy="2.40127e-06" iyz="-5.3128971e-11" izz="1.674842e-06"/>
    </inertial>
  </link>
  <joint name="joint_3_0" type="revolute">
    <axis xyz="0 1 0"/>
    <limit effort="15" lower="-0.227" upper="1.618" velocity="7"/>
    <parent link="link_2_0"/>
    <child link="link_3_0"/>
    <origin xyz="0 0 0.0384"/>
    <dynamics damping="10" friction="12"/>
  </joint>
  <!-- [FINGER TIP] -->
  <link name="link_3_0_tip">
    <visual>
      <geometry>
        <mesh filename="assets/finger_tip.stl" scale="0.001 0.001 0.001"/>
      </geometry>
       <origin rpy="0 0 -1.57" xyz="-0.05482 -0.01393 -0.00995"/>
      <material name="white">
        <color rgba=".9 .9 .9 1"/>
      </material>
    </visual>
    <collision>
      <geometry>
        <mesh filename="assets/finger_tip.stl" scale="0.001 0.001 0.001"/>
      </geometry>
       <origin rpy="0 0 -1.57" xyz="-0.05482 -0.01393 -0.00995"/>
    </collision>
    <inertial>
      <mass value="0.00"/>
      <origin rpy="0 0 0" xyz="0 0 0"/>
      <inertia ixx="9.68e-07" ixy="0" ixz="0" iyy="9.68e-07" iyz="0" izz="9.68e-07"/>
    </inertial>
  </link>
  <joint name="joint_3_0_tip" type="fixed">
    <parent link="link_3_0"/>
    <child link="link_3_0_tip"/>
    <origin rpy="0 0 0" xyz="0 0 0.0267"/>
  </joint>
  <!-- [LINK 0, 4, 8] -->
  <link name="link_4_0">
    <visual>
      <geometry>
        <mesh filename="assets/l1.stl" scale="0.001 0.001 0.001"/>
      </geometry>
        <origin rpy="0 0 -1.57" xyz="-0.025 -0.019 0.165"/>
      <material name="black"/>
    </visual>
    <collision>
     <geometry>
        <mesh filename="assets/l1.stl" scale="0.001 0.001 0.001"/>
      </geometry>
        <origin rpy="0 0 -1.57" xyz="-0.025 -0.019 0.165"/>
    </collision>
    <inertial>
      <mass value="0.0176"/>
      <origin rpy="0 0 0" xyz="0 0 0"/>
      <inertia ixx="1.2854008e-05" ixy="2.04e-08" ixz="1.89e-06" iyy="1.225e-05" iyz="1.51e-07" izz="2.999e-06"/>
    </inertial>
  </link>
  <joint name="joint_4_0" type="revolute">
    <axis xyz="0 0 1"/>
    <limit effort="15" lower="-0.47" upper="0.47" velocity="7"/>
    <parent link="palm_link"/>
    <child link="link_4_0"/>
    <origin rpy="0.0 0 0" xyz="0 0.00 -0.0079"/>
    <dynamics damping="3" friction="10"/>
  </joint>
  <!-- [LINK 1, 5, 9] -->
  <link name="link_5_0">
    <visual>
      <geometry>
        <mesh filename="assets/l2.stl" scale="0.001 0.001 0.001"/>
      </geometry>
      <origin rpy="0 0 -1.57" xyz="-0.025 -0.019 0.145"/>
      <material name="black"/>
    </visual>
    <collision>
      <geometry>
        <mesh filename="assets/l2.stl" scale="0.001 0.001 0.001"/>
      </geometry>
      <origin rpy="0 0 -1.57" xyz="-0.025 -0.019 0.145"/>
    </collision>
    <inertial>
      <mass value="0.066"/>
      <origin rpy="0 0 0" xyz="0 0 0"/>
      <inertia ixx="6.2497616e-06" ixy="0.0000e-06" ixz="-1.892683e-06" iyy="3.1284129e-05" iyz="0.0000e-06" izz="2.9004797e-05"/>
    </inertial>
  </link>
  <joint name="joint_5_0" type="revolute">
    <limit effort="15" lower="-0.196" upper="1.8" velocity="7"/>
    <axis xyz="0 1 0"/>
    <parent link="link_4_0"/>
    <child link="link_5_0"/>
    <origin xyz="0 0 0.021"/>
    <dynamics damping="3" friction="5"/>
  </joint>
  <!-- [LINK 2, 6, 10]-->
  <link name="link_6_0">
    <visual>
      <geometry>
        <mesh filename="assets/l3.stl" scale="0.001 0.001 0.001"/>
      </geometry>
      <origin rpy="0 0 -1.57" xyz="-0.025 -0.019 0.0945"/>
      <material name="black"/>
    </visual>
    <collision>
      <geometry>
        <mesh filename="assets/l3.stl" scale="0.001 0.001 0.001"/>
      </geometry>
      <origin rpy="0 0 -1.57" xyz="-0.025 -0.019 0.0945"/>
    </collision>
    <inertial>
      <mass value="0.0366"/>
      <origin rpy="0 0 0" xyz="0 0 0"/>
      <inertia ixx="3.8070280e-06" ixy="5.7154287e-03" ixz="-9.9708657e-07" iyy="1.4547214e-05" iyz="2.632663e-04" izz="1.2905337e-05"/>
    </inertial>
  </link>
  <joint name="joint_6_0" type="revolute">
    <axis xyz="0 1 0"/>
    <limit effort="15" lower="-0.174" upper="1.709" velocity="7"/>
    <parent link="link_5_0"/>
    <child link="link_6_0"/>
    <origin xyz="0 0 0.051"/>
    <dynamics damping="8" friction="10"/>
  </joint>
  <!-- [LINK 3, 7, 11] -->
  <link name="link_7_0">
    <visual>
      <geometry>
        <mesh filename="assets/l4.stl" scale="0.001 0.001 0.001"/>
      </geometry>
      <origin rpy="0 0 -1.57" xyz="-0.025 -0.019 0.0561"/>
      <material name="black"/>
    </visual>
    <collision>
      <geometry>
        <mesh filename="assets/l4.stl" scale="0.001 0.001 0.001"/>
      </geometry>
      <origin rpy="0 0 -1.57" xyz="-0.025 -0.019 0.0561"/>
    </collision>
    <inertial>
      <mass value="0.00569"/>
      <origin rpy="0 0 0" xyz="0 0 0"/>
      <inertia ixx="1.176928e-06" ixy="5.0891669e-03" ixz="0.000000e-06" iyy="2.40127e-06" iyz="-5.3128971e-11" izz="1.674842e-06"/>
    </inertial>
  </link>
  <joint name="joint_7_0" type="revolute">
    <axis xyz="0 1 0"/>
    <limit effort="15" lower="-0.227" upper="1.618" velocity="7"/>
    <parent link="link_6_0"/>
    <child link="link_7_0"/>
    <origin xyz="0 0 0.0384"/>
    <dynamics damping="10" friction="12"/>
  </joint>
  <!-- [FINGER TIP] -->
  <link name="link_7_0_tip">
    <visual>
      <geometry>
        <mesh filename="assets/finger_tip.stl" scale="0.001 0.001 0.001"/>
      </geometry>
       <origin rpy="0 0 -1.57" xyz="-0.05482 -0.01393 -0.00995"/>
      <material name="white">
        <color rgba=".9 .9 .9 1"/>
      </material>
    </visual>
    <collision>
      <geometry>
        <mesh filename="assets/finger_tip.stl" scale="0.001 0.001 0.001"/>
      </geometry>
       <origin rpy="0 0 -1.57" xyz="-0.05482 -0.01393 -0.00995"/>
    </collision>
    <inertial>
      <mass value="0.00"/>
      <origin rpy="0 0 0" xyz="0 0 0"/>
      <inertia ixx="9.68e-07" ixy="0" ixz="0" iyy="9.68e-07" iyz="0" izz="9.68e-07"/>
    </inertial>
  </link>
  <joint name="joint_7_0_tip" type="fixed">
    <parent link="link_7_0"/>
    <child link="link_7_0_tip"/>
    <origin rpy="0 0 0" xyz="0 0 0.0267"/>
  </joint>
  <!-- [LINK 0, 4, 8] -->
    <link name="link_8_0">
    <visual>
      <geometry>
        <mesh filename="assets/l1.stl" scale="0.001 0.001 0.001"/>
      </geometry>
      <origin rpy="0 0 -1.57" xyz="-0.025 -0.019 0.165"/>
      <material name="black">
        <color rgba="0.2 0.2 0.2 1"/>
      </material>
    </visual>
    <collision>
      <geometry>
        <mesh filename="assets/l1.stl" scale="0.001 0.001 0.001"/>
      </geometry>
      <origin rpy="0 0 -1.57" xyz="-0.025 -0.019 0.165"/>
    </collision>
    <inertial>
      <mass value="0.0176"/>
      <origin rpy="0 0 0" xyz="0 0 0"/>
      <inertia ixx="1.2854008e-05" ixy="2.04e-08" ixz="1.89e-06" iyy="1.225e-05" iyz="1.51e-07" izz="2.999e-06"/>
    </inertial>
  </link>
  <joint name="joint_8_0" type="revolute">
    <axis xyz="0 0 1"/>
    <limit effort="15" lower="-0.47" upper="0.47" velocity="7"/>
    <parent link="palm_link"/>
    <child link="link_8_0"/>
    <origin rpy="0.08726646255 0 0" xyz="0.0025 -0.0405 -0.00945"/>
    <dynamics damping="3" friction="10"/>
  </joint>
  <!-- [LINK 1, 5, 9] -->
  <link name="link_9_0">
    <visual>
      <geometry>
        <mesh filename="assets/l2.stl" scale="0.001 0.001 0.001"/>
      </geometry>
      <origin rpy="0 0 -1.57" xyz="-0.025 -0.019 0.145"/>
      <material name="black"/>
    </visual>
    <collision>
      <geometry>
        <mesh filename="assets/l2.stl" scale="0.001 0.001 0.001"/>
      </geometry>
      <origin rpy="0 0 -1.57" xyz="-0.025 -0.019 0.145"/>
    </collision>
    <inertial>
      <mass value="0.066"/>
      <origin rpy="0 0 0" xyz="0 0 0"/>
      <inertia ixx="6.2497616e-06" ixy="0.0000e-06" ixz="-1.892683e-06" iyy="3.1284129e-05" iyz="0.0000e-06" izz="2.9004797e-05"/>
    </inertial>
  </link>
  <joint name="joint_9_0" type="revolute">
    <limit effort="15" lower="-0.196" upper="1.8" velocity="7"/>
    <axis xyz="0 1 0"/>
    <parent link="link_8_0"/>
    <child link="link_9_0"/>
    <origin xyz="0 0 0.021"/>
    <dynamics damping="3" friction="5"/>
  </joint>
  <!-- [LINK 2, 6, 10]-->
  <link name="link_10_0">
    <visual>
      <geometry>
        <mesh filename="assets/l3.stl" scale="0.001 0.001 0.001"/>
      </geometry>
      <origin rpy="0 0 -1.57" xyz="-0.025 -0.019 0.0945"/>
      <material name="black"/>
    </visual>
    <collision>
      <geometry>
        <mesh filename="assets/l3.stl" scale="0.001 0.001 0.001"/>
      </geometry>
      <origin rpy="0 0 -1.57" xyz="-0.025 -0.019 0.0945"/>
    </collision>
    <inertial>
      <mass value="0.0366"/>
      <origin rpy="0 0 0" xyz="0 0 0"/>
      <inertia ixx="3.8070280e-06" ixy="5.7154287e-03" ixz="-9.9708657e-07" iyy="1.4547214e-05" iyz="2.632663e-04" izz="1.2905337e-05"/>
    </inertial>
  </link>
  <joint name="joint_10_0" type="revolute">
    <axis xyz="0 1 0"/>
    <limit effort="15" lower="-0.174" upper="1.709" velocity="7"/>
    <parent link="link_9_0"/>
    <child link="link_10_0"/>
    <origin xyz="0 0 0.051"/>
    <dynamics damping="8" friction="10"/>
  </joint>
  <!-- [LINK 3, 7, 11] -->
  <link name="link_11_0">
    <visual>
      <geometry>
        <mesh filename="assets/l4.stl" scale="0.001 0.001 0.001"/>
      </geometry>
      <origin rpy="0 0 -1.57" xyz="-0.025 -0.019 0.0561"/>
      <material name="black"/>
    </visual>
    <collision>
      <geometry>
        <mesh filename="assets/l4.stl" scale="0.001 0.001 0.001"/>
      </geometry>
      <origin rpy="0 0 -1.57" xyz="-0.025 -0.019 0.0561"/>
    </collision>
    <inertial>
      <mass value="0.00569"/>
      <origin rpy="0 0 0" xyz="0 0 0"/>
      <inertia ixx="1.176928e-06" ixy="5.0891669e-03" ixz="0.000000e-06" iyy="2.40127e-06" iyz="-5.3128971e-11" izz="1.674842e-06"/>
    </inertial>
  </link>
  <joint name="joint_11_0" type="revolute">
    <axis xyz="0 1 0"/>
    <limit effort="15" lower="-0.227" upper="1.618" velocity="7"/>
    <parent link="link_10_0"/>
    <child link="link_11_0"/>
    <origin xyz="0 0 0.0384"/>
    <dynamics damping="10" friction="12"/>
  </joint>
  <!-- [FINGER TIP] -->
  <link name="link_11_0_tip">
    <visual>
      <geometry>
        <mesh filename="assets/finger_tip.stl" scale="0.001 0.001 0.001"/>
      </geometry>
      <origin rpy="0 0 -1.57" xyz="-0.05482 -0.01393 -0.00995"/>
      <material name="white">
        <color rgba=".9 .9 .9 1"/>
      </material>
    </visual>
    <collision>
      <geometry>
        <mesh filename="assets/finger_tip.stl" scale="0.001 0.001 0.001"/>
      </geometry>
      <origin rpy="0 0 -1.57" xyz="-0.05482 -0.01393 -0.00995"/>
    </collision>
    <inertial>
      <mass value="0.00"/>
      <origin rpy="0 0 0" xyz="0 0 0"/>
      <inertia ixx="9.68e-07" ixy="0" ixz="0" iyy="9.68e-07" iyz="0" izz="9.68e-07"/>
    </inertial>
  </link>
  <joint name="joint_11_0_tip" type="fixed">
    <parent link="link_11_0"/>
    <child link="link_11_0_tip"/>
    <origin rpy="0 0 0" xyz="0 0 0.0267"/>
  </joint>
  <!-- THUMB -->
  <!-- [LINK 12] -->
  <link name="link_12_0">
    <visual>
      <geometry>
        <mesh filename="assets/t1_set.stl" scale="0.001 0.001 0.001"/>
      </geometry>
      <origin rpy="3.926991 3.14 3.14" xyz="0.021 -0.1145 0.0725"/>
      <material name="black">
        <color rgba=".2 .2 .2 1"/>
      </material>
    </visual>
    <collision>
      <geometry>
        <mesh filename="assets/t1_set.stl" scale="0.001 0.001 0.001"/>
      </geometry>
      <origin rpy="3.926991 3.14 3.14" xyz="0.021 -0.1145 0.0725"/>
    </collision>
    <inertial>
      <mass value="0.0446"/>
      <origin rpy="0 0 0" xyz="0 0 0"/>
      <inertia ixx="5.44e-5" ixy="4.0e-07" ixz="-1.12e-07" iyy="9.19e-06" iyz="1.07e-05" izz="4.8e-05"/>
    </inertial>
  </link>
  <joint name="joint_12_0" type="revolute">
    <axis xyz="-1 0 0"/>
    <limit effort="15" lower="0.00" upper="1.78" velocity="7"/>
    <parent link="palm_link"/>
    <child link="link_12_0"/>
    <origin rpy="0 -1.65806278845 -1.5707963259" xyz="0.002 0.027 -0.06342"/>
    <dynamics damping="3" friction="10"/>
  </joint>
  <!-- [LINK 13] -->
  <link name="link_13_0">
    <visual>
      <geometry>
        <mesh filename="assets/t2_set.stl" scale="0.001 0.001 0.001"/>
      </geometry>
      <origin rpy="3.14 3.14 1.57" xyz="-0.138 -0.0605 0.2143"/>
      <material name="black">
        <color rgba=".2 .2 .2 1"/>
      </material>
    </visual>
    <collision>
      <geometry>
        <mesh filename="assets/t2_set.stl" scale="0.001 0.001 0.001"/>
      </geometry>
      <origin rpy="3.14 3.14 1.57" xyz="-0.138 -0.0605 0.2143"/>
    </collision>
    <inertial>
      <mass value="0.0173"/>
      <origin rpy="0 0 0" xyz="0 0 0"/>
      <inertia ixx="1.52e-05" ixy="-2.09e-08" ixz="-9.8e-09" iyy="1.3323e-05" iyz="-2.04e-06" izz="2.85e-06"/>
    </inertial>
  </link>
  <joint name="joint_13_0" type="revolute">
    <axis xyz="0 0 1"/>
       <limit effort="15" lower="-0.26" upper="1.78" velocity="7"/>
    <parent link="link_12_0"/>
    <child link="link_13_0"/>
    <origin xyz="-0.001 0.00 0.06874"/>
    <dynamics damping="3" friction="5"/>
  </joint>
  <!-- [LINK 14] -->
  <link name="link_14_0">
    <visual>
      <geometry>
        <mesh filename="assets/t3_set.stl" scale="0.001 0.001 0.001"/>
      </geometry>
      <origin rpy="3.14 3.14 1.57" xyz="-0.1265 -0.061 0.166"/>
      <material name="black">
      </material>
    </visual>
    <collision>
      <geometry>
        <mesh filename="assets/t3_set.stl" scale="0.001 0.001 0.001"/>
      </geometry>
      <origin rpy="3.14 3.14 1.57" xyz="-0.1265 -0.061 0.166"/>
    </collision>
    <inertial>
      <mass value="0.03607"/>
      <origin rpy="0 0 0" xyz="0 0 0"/>
      <inertia ixx="3.7e-06" ixy="2.43e-07" ixz="6.48e-07" iyy="1.54e-05" iyz="-3.11e-08" izz="1.388e-05"/>
    </inertial>
  </link>
  <joint name="joint_14_0" type="revolute">
    <axis xyz="0 1 0"/>
    <!--<limit effort="15" lower="-0.54" upper="1.53" velocity="7"/>-->
           <limit effort="15" lower="-0.05" upper="1.85" velocity="7"/>
    <parent link="link_13_0"/>
    <child link="link_14_0"/>
    <origin xyz="0 0 0.00"/>
    <dynamics damping="3" friction="10"/>
  </joint>
  <!-- [LINK 15] -->
  <link name="link_15_0">
    <visual>
      <geometry>
         <mesh filename="assets/t4_set.stl" scale="0.001 0.001 0.001"/>
      </geometry>
      <origin rpy="3.14 3.14 1.57" xyz="-0.149 -0.061 0.096"/>
      <material name="black">
      </material>
    </visual>
    <collision>
      <geometry>
         <mesh filename="assets/t4_set.stl" scale="0.001 0.001 0.001"/>
      </geometry>
      <origin rpy="3.14 3.14 1.57" xyz="-0.149 -0.061 0.096"/>
    </collision>
    <inertial>
      <mass value="0.0338"/>
      <origin rpy="0 0 0" xyz="0 0 0"/>
      <inertia ixx="2.94e-06" ixy="1.244e-07" ixz="3.52e-07" iyy="1.13e-05" iyz="-3.11e-08" izz="1.06e-05"/>
    </inertial>
  </link>
  <joint name="joint_15_0" type="revolute">
    <axis xyz="0 1 0"/>
    <limit effort="15" lower="-0.09" upper="1.80" velocity="7"/>
    <parent link="link_14_0"/>
    <child link="link_15_0"/>
    <origin xyz="0 0 0.038"/>
    <dynamics damping="3" friction="12"/>
  </joint>
  <!-- [FINGER TIP] -->
  <link name="link_15_0_tip">
    <visual>
      <geometry>
        <mesh filename="assets/finger_tip_silicon.stl" scale="0.001 0.001 0.001"/>
      </geometry>
      <origin rpy="0 0 3.14" xyz="-0.014 0.0545 -0.0172"/>
      <material name="white">
        <color rgba=".9 .9 .9 1"/>
      </material>
    </visual>
    <collision>
      <geometry>
        <mesh filename="assets/finger_tip_silicon.stl" scale="0.001 0.001 0.001"/>
      </geometry>
      <origin rpy="0 0 3.14" xyz="-0.014 0.0545 -0.0172"/>
    </collision>
    <inertial>
      <mass value="0.00"/>
      <origin rpy="0 0 0" xyz="0 0 0"/>
      <inertia ixx="9.68e-07" ixy="0" ixz="0" iyy="9.68e-07" iyz="0" izz="9.68e-07"/>
    </inertial>
  </link>
  <joint name="joint_15_0_tip" type="fixed">
    <parent link="link_15_0"/>
    <child link="link_15_0_tip"/>
    <origin rpy="0 0 0" xyz="0 0 0.05"/>
  </joint>
  <!-- ============================================================================= -->
  <!-- THUMB MACRO -->
  <!-- END THUMB MACRO -->
  <!-- THREE FINGER MACRO -->
  <!-- [[END]] THREE FINGER MACRO -->

  <joint name="fr3_allegro_joint" type="fixed">
    <parent link="fr3_link8"/>
    <child link="palm_link"/>
    <origin rpy="0 0 0" xyz="0 0 0"/>
  </joint>

</robot>
