<mujoco model="allegro_hand_right">
  <compiler angle="radian" autolimits="true"/>

  <asset>
    <mesh name="palm" content_type="model/stl" file="assets/palm.stl" scale="0.001 0.001 0.001"/>
    <mesh name="new_l1" content_type="model/stl" file="assets/new_l1.stl" scale="0.001 0.001 0.001"/>
    <mesh name="new_l2" content_type="model/stl" file="assets/new_l2.stl" scale="0.001 0.001 0.001"/>
    <mesh name="new_l3" content_type="model/stl" file="assets/new_l3.stl" scale="0.001 0.001 0.001"/>
    <mesh name="new_l4" content_type="model/stl" file="assets/new_l4.stl" scale="0.001 0.001 0.001"/>
    <mesh name="finger_tip" content_type="model/stl" file="assets/finger_tip.stl" scale="0.001 0.001 0.001"/>
    <mesh name="t1_set" content_type="model/stl" file="assets/t1_set.stl" scale="0.001 0.001 0.001"/>
    <mesh name="t2_set" content_type="model/stl" file="assets/t2_set.stl" scale="0.001 0.001 0.001"/>
    <mesh name="t3_set" content_type="model/stl" file="assets/t3_set.stl" scale="0.001 0.001 0.001"/>
    <mesh name="t4_set" content_type="model/stl" file="assets/t4_set.stl" scale="0.001 0.001 0.001"/>
    <mesh name="finger_tip_silicon" content_type="model/stl" file="assets/finger_tip_silicon.stl" scale="0.001 0.001 0.001"/>
  </asset>

  <worldbody>
    <geom pos="0.02 0 -0.1" quat="0.000563312 -0.706825 0.707388 0.000562864" type="mesh" contype="0" conaffinity="0" group="1" density="0" rgba="0.2 0.2 0.2 1" mesh="palm"/>
    <geom pos="0.02 0 -0.1" quat="0.000563312 -0.706825 0.707388 0.000562864" type="mesh" rgba="0.2 0.2 0.2 1" mesh="palm"/>
    <body name="link_0_0" pos="0.0005 0.0425 -0.005" quat="0.999048 -0.0436194 0 0">
      <joint name="joint_0_0" pos="0 0 0" axis="0 0 1" range="-0.3 0.3" actuatorfrcrange="-15 15" limited="true" damping="3"/>
      <geom pos="-0.0625 -0.022 0.167" quat="0.707388 0 0 -0.706825" type="mesh" contype="0" conaffinity="0" group="1" density="0" rgba="0.2 0.2 0.2 1" mesh="new_l1"/>
      <geom pos="-0.0625 -0.022 0.167" quat="0.707388 0 0 -0.706825" type="mesh" rgba="0.2 0.2 0.2 1" mesh="new_l1"/>
      <body name="link_1_0" pos="0 0 0.017">
        <joint name="joint_1_0" pos="0 0 0" axis="0 1 0" range="-0.01 1.6" actuatorfrcrange="-15 15" limited="true" damping="3"/>
        <geom pos="-0.0625 -0.022 0.1495" quat="0.707388 0 0 -0.706825" type="mesh" contype="0" conaffinity="0" group="1" density="0" rgba="0.2 0.2 0.2 1" mesh="new_l2"/>
        <geom pos="-0.0625 -0.022 0.1495" quat="0.707388 0 0 -0.706825" type="mesh" rgba="0.2 0.2 0.2 1" mesh="new_l2"/>
        <body name="link_2_0" pos="0 0 0.0431">
          <joint name="joint_2_0" pos="0 0 0" axis="0 1 0" range="-0.07 1.86" actuatorfrcrange="-15 15" limited="true" damping="8"/>
          <geom pos="-0.0625 -0.022 0.1065" quat="0.707388 0 0 -0.706825" type="mesh" contype="0" conaffinity="0" group="1" density="0" rgba="0.2 0.2 0.2 1" mesh="new_l3"/>
          <geom pos="-0.0625 -0.022 0.1065" quat="0.707388 0 0 -0.706825" type="mesh" rgba="0.2 0.2 0.2 1" mesh="new_l3"/>
          <body name="link_3_0" pos="0 0 0.038">
            <joint name="joint_3_0" pos="0 0 0" axis="0 1 0" range="-0.02 2.01" actuatorfrcrange="-15 15" limited="true" damping="10"/>
            <geom pos="-0.0625 -0.022 0.0685" quat="0.707388 0 0 -0.706825" type="mesh" contype="0" conaffinity="0" group="1" density="0" rgba="0.2 0.2 0.2 1" mesh="new_l4"/>
            <geom pos="-0.0625 -0.022 0.0685" quat="0.707388 0 0 -0.706825" type="mesh" rgba="0.2 0.2 0.2 1" mesh="new_l4"/>
            <geom pos="-0.05482 -0.01493 0.02205" quat="0.707388 0 0 -0.706825" type="mesh" contype="0" conaffinity="0" group="1" density="0" rgba="0.9 0.9 0.9 1" mesh="finger_tip"/>
            <geom pos="-0.05482 -0.01493 0.02205" quat="0.707388 0 0 -0.706825" type="mesh" rgba="0.9 0.9 0.9 1" mesh="finger_tip"/>
          </body>
        </body>
      </body>
    </body>
    <body name="link_4_0" pos="0 0 -0.002">
      <joint name="joint_4_0" pos="0 0 0" axis="0 0 1" range="-0.26 0.26" actuatorfrcrange="-15 15" limited="true" damping="3"/>
      <geom pos="-0.0625 -0.022 0.167" quat="0.707388 0 0 -0.706825" type="mesh" contype="0" conaffinity="0" group="1" density="0" rgba="0.2 0.2 0.2 1" mesh="new_l1"/>
      <geom pos="-0.0625 -0.022 0.167" quat="0.707388 0 0 -0.706825" type="mesh" rgba="0.2 0.2 0.2 1" mesh="new_l1"/>
      <body name="link_5_0" pos="0 0 0.017">
        <joint name="joint_5_0" pos="0 0 0" axis="0 1 0" range="-0.21 1.79" actuatorfrcrange="-15 15" limited="true" damping="3"/>
        <geom pos="-0.0625 -0.022 0.1495" quat="0.707388 0 0 -0.706825" type="mesh" contype="0" conaffinity="0" group="1" density="0" rgba="0.2 0.2 0.2 1" mesh="new_l2"/>
        <geom pos="-0.0625 -0.022 0.1495" quat="0.707388 0 0 -0.706825" type="mesh" rgba="0.2 0.2 0.2 1" mesh="new_l2"/>
        <body name="link_6_0" pos="0 0 0.0431">
          <joint name="joint_6_0" pos="0 0 0" axis="0 1 0" range="-0.12 1.86" actuatorfrcrange="-15 15" limited="true" damping="8"/>
          <geom pos="-0.0625 -0.022 0.1065" quat="0.707388 0 0 -0.706825" type="mesh" contype="0" conaffinity="0" group="1" density="0" rgba="0.2 0.2 0.2 1" mesh="new_l3"/>
          <geom pos="-0.0625 -0.022 0.1065" quat="0.707388 0 0 -0.706825" type="mesh" rgba="0.2 0.2 0.2 1" mesh="new_l3"/>
          <body name="link_7_0" pos="0 0 0.038">
            <joint name="joint_7_0" pos="0 0 0" axis="0 1 0" range="-0.21 1.85" actuatorfrcrange="-15 15" limited="true" damping="10"/>
            <geom pos="-0.0625 -0.022 0.0685" quat="0.707388 0 0 -0.706825" type="mesh" contype="0" conaffinity="0" group="1" density="0" rgba="0.2 0.2 0.2 1" mesh="new_l4"/>
            <geom pos="-0.0625 -0.022 0.0685" quat="0.707388 0 0 -0.706825" type="mesh" rgba="0.2 0.2 0.2 1" mesh="new_l4"/>
            <geom pos="-0.05482 -0.01493 0.02205" quat="0.707388 0 0 -0.706825" type="mesh" contype="0" conaffinity="0" group="1" density="0" rgba="0.9 0.9 0.9 1" mesh="finger_tip"/>
            <geom pos="-0.05482 -0.01493 0.02205" quat="0.707388 0 0 -0.706825" type="mesh" rgba="0.9 0.9 0.9 1" mesh="finger_tip"/>
          </body>
        </body>
      </body>
    </body>
    <body name="link_8_0" pos="0.0005 -0.0425 -0.005" quat="0.999048 0.0436194 0 0">
      <joint name="joint_8_0" pos="0 0 0" axis="0 0 1" range="-0.26 0.29" actuatorfrcrange="-15 15" limited="true" damping="3"/>
      <geom pos="-0.0625 -0.022 0.167" quat="0.707388 0 0 -0.706825" type="mesh" contype="0" conaffinity="0" group="1" density="0" rgba="0.2 0.2 0.2 1" mesh="new_l1"/>
      <geom pos="-0.0625 -0.022 0.167" quat="0.707388 0 0 -0.706825" type="mesh" rgba="0.2 0.2 0.2 1" mesh="new_l1"/>
      <body name="link_9_0" pos="0 0 0.017">
        <joint name="joint_9_0" pos="0 0 0" axis="0 1 0" range="-0.21 1.79" actuatorfrcrange="-15 15" limited="true" damping="3"/>
        <geom pos="-0.0625 -0.022 0.1495" quat="0.707388 0 0 -0.706825" type="mesh" contype="0" conaffinity="0" group="1" density="0" rgba="0.2 0.2 0.2 1" mesh="new_l2"/>
        <geom pos="-0.0625 -0.022 0.1495" quat="0.707388 0 0 -0.706825" type="mesh" rgba="0.2 0.2 0.2 1" mesh="new_l2"/>
        <body name="link_10_0" pos="0 0 0.0431">
          <joint name="joint_10_0" pos="0 0 0" axis="0 1 0" range="-0.12 1.86" actuatorfrcrange="-15 15" limited="true" damping="8"/>
          <geom pos="-0.0625 -0.022 0.1065" quat="0.707388 0 0 -0.706825" type="mesh" contype="0" conaffinity="0" group="1" density="0" rgba="0.2 0.2 0.2 1" mesh="new_l3"/>
          <geom pos="-0.0625 -0.022 0.1065" quat="0.707388 0 0 -0.706825" type="mesh" rgba="0.2 0.2 0.2 1" mesh="new_l3"/>
          <body name="link_11_0" pos="0 0 0.038">
            <joint name="joint_11_0" pos="0 0 0" axis="0 1 0" range="-0.21 1.85" actuatorfrcrange="-15 15" limited="true" damping="10"/>
            <geom pos="-0.0625 -0.022 0.0685" quat="0.707388 0 0 -0.706825" type="mesh" contype="0" conaffinity="0" group="1" density="0" rgba="0.2 0.2 0.2 1" mesh="new_l4"/>
            <geom pos="-0.0625 -0.022 0.0685" quat="0.707388 0 0 -0.706825" type="mesh" rgba="0.2 0.2 0.2 1" mesh="new_l4"/>
            <geom pos="-0.05482 -0.01493 0.02205" quat="0.707388 0 0 -0.706825" type="mesh" contype="0" conaffinity="0" group="1" density="0" rgba="0.9 0.9 0.9 1" mesh="finger_tip"/>
            <geom pos="-0.05482 -0.01493 0.02205" quat="0.707388 0 0 -0.706825" type="mesh" rgba="0.9 0.9 0.9 1" mesh="finger_tip"/>
          </body>
        </body>
      </body>
    </body>
    <body name="link_12_0" pos="0.002 0.027 -0.06342" quat="0.477714 -0.521334 -0.521334 -0.477714">
      <joint name="joint_12_0" pos="0 0 0" axis="-1 0 0" range="0 1.78" actuatorfrcrange="-15 15" limited="true" damping="3"/>
      <geom pos="0.021 -0.1145 0.0725" quat="0.923879 0.382684 0.000430969 -0.00104045" type="mesh" contype="0" conaffinity="0" group="1" density="0" rgba="0.2 0.2 0.2 1" mesh="t1_set"/>
      <geom pos="0.021 -0.1145 0.0725" quat="0.923879 0.382684 0.000430969 -0.00104045" type="mesh" rgba="0.2 0.2 0.2 1" mesh="t1_set"/>
      <body name="link_13_0" pos="-0.001 0 0.06874">
        <joint name="joint_13_0" pos="0 0 0" axis="0 0 1" range="-0.26 1.65" actuatorfrcrange="-15 15" limited="true" damping="3"/>
        <geom pos="-0.138 -0.0605 0.2143" quat="0.706825 4.48402e-07 0.00112618 -0.707387" type="mesh" contype="0" conaffinity="0" group="1" density="0" rgba="0.2 0.2 0.2 1" mesh="t2_set"/>
        <geom pos="-0.138 -0.0605 0.2143" quat="0.706825 4.48402e-07 0.00112618 -0.707387" type="mesh" rgba="0.2 0.2 0.2 1" mesh="t2_set"/>
        <body name="link_14_0">
          <joint name="joint_14_0" pos="0 0 0" axis="0 1 0" range="-0.05 1.85" actuatorfrcrange="-15 15" limited="true" damping="3"/>
          <geom pos="-0.1265 -0.061 0.166" quat="0.706825 4.48402e-07 0.00112618 -0.707387" type="mesh" contype="0" conaffinity="0" group="1" density="0" rgba="0.2 0.2 0.2 1" mesh="t3_set"/>
          <geom pos="-0.1265 -0.061 0.166" quat="0.706825 4.48402e-07 0.00112618 -0.707387" type="mesh" rgba="0.2 0.2 0.2 1" mesh="t3_set"/>
          <body name="link_15_0" pos="0 0 0.038">
            <joint name="joint_15_0" pos="0 0 0" axis="0 1 0" range="-0.09 1.8" actuatorfrcrange="-15 15" limited="true" damping="3"/>
            <geom pos="-0.149 -0.061 0.096" quat="0.706825 4.48402e-07 0.00112618 -0.707387" type="mesh" contype="0" conaffinity="0" group="1" density="0" rgba="0.2 0.2 0.2 1" mesh="t4_set"/>
            <geom pos="-0.149 -0.061 0.096" quat="0.706825 4.48402e-07 0.00112618 -0.707387" type="mesh" rgba="0.2 0.2 0.2 1" mesh="t4_set"/>
            <geom pos="-0.014 0.0545 0.0328" quat="0.000796327 0 0 1" type="mesh" contype="0" conaffinity="0" group="1" density="0" rgba="0.9 0.9 0.9 1" mesh="finger_tip_silicon"/>
            <geom pos="-0.014 0.0545 0.0328" quat="0.000796327 0 0 1" type="mesh" rgba="0.9 0.9 0.9 1" mesh="finger_tip_silicon"/>
          </body>
        </body>
      </body>
    </body>
  </worldbody>

<contact>
  <exclude body1="link_0_0" body2="link_1_0"/>
  <exclude body1="link_1_0" body2="link_2_0"/>
  <exclude body1="link_2_0" body2="link_3_0"/>
  <exclude body1="link_4_0" body2="link_5_0"/>
  <exclude body1="link_5_0" body2="link_6_0"/>
  <exclude body1="link_6_0" body2="link_7_0"/>
  <exclude body1="link_8_0" body2="link_9_0"/>
  <exclude body1="link_9_0" body2="link_10_0"/>
  <exclude body1="link_10_0" body2="link_11_0"/>
  <exclude body1="link_12_0" body2="link_13_0"/>
  <exclude body1="link_13_0" body2="link_14_0"/>
  <exclude body1="link_14_0" body2="link_15_0"/>
</contact>

<actuator>
  <motor name="act_joint_0_0" joint="joint_0_0" ctrlrange="-15 15" forcerange="-15 15"/>
  <motor name="act_joint_1_0" joint="joint_1_0" ctrlrange="-15 15" forcerange="-15 15"/>
  <motor name="act_joint_2_0" joint="joint_2_0" ctrlrange="-15 15" forcerange="-15 15"/>
  <motor name="act_joint_3_0" joint="joint_3_0" ctrlrange="-15 15" forcerange="-15 15"/>
  <motor name="act_joint_4_0" joint="joint_4_0" ctrlrange="-15 15" forcerange="-15 15"/>
  <motor name="act_joint_5_0" joint="joint_5_0" ctrlrange="-15 15" forcerange="-15 15"/>
  <motor name="act_joint_6_0" joint="joint_6_0" ctrlrange="-15 15" forcerange="-15 15"/>
  <motor name="act_joint_7_0" joint="joint_7_0" ctrlrange="-15 15" forcerange="-15 15"/>
  <motor name="act_joint_8_0" joint="joint_8_0" ctrlrange="-15 15" forcerange="-15 15"/>
  <motor name="act_joint_9_0" joint="joint_9_0" ctrlrange="-15 15" forcerange="-15 15"/>
  <motor name="act_joint_10_0" joint="joint_10_0" ctrlrange="-15 15" forcerange="-15 15"/>
  <motor name="act_joint_11_0" joint="joint_11_0" ctrlrange="-15 15" forcerange="-15 15"/>
  <motor name="act_joint_12_0" joint="joint_12_0" ctrlrange="-15 15" forcerange="-15 15"/>
  <motor name="act_joint_13_0" joint="joint_13_0" ctrlrange="-15 15" forcerange="-15 15"/>
  <motor name="act_joint_14_0" joint="joint_14_0" ctrlrange="-15 15" forcerange="-15 15"/>
  <motor name="act_joint_15_0" joint="joint_15_0" ctrlrange="-15 15" forcerange="-15 15"/>
</actuator>
</mujoco>
